Epoch 0/1
----------
  0%|                                                                                                                                                                                              | 0/266 [00:00<?, ?it/s]
Traceback (most recent call last):
  File "/opt/conda/lib/python3.8/runpy.py", line 194, in _run_module_as_main
    return _run_code(code, main_globals, None,
  File "/opt/conda/lib/python3.8/runpy.py", line 87, in _run_code
    exec(code, run_globals)
  File "/opt/ml/.vscode-server/extensions/ms-python.python-2021.8.1159798656/pythonFiles/lib/python/debugpy/__main__.py", line 45, in <module>
    cli.main()
  File "/opt/ml/.vscode-server/extensions/ms-python.python-2021.8.1159798656/pythonFiles/lib/python/debugpy/../debugpy/server/cli.py", line 444, in main
    run()
  File "/opt/ml/.vscode-server/extensions/ms-python.python-2021.8.1159798656/pythonFiles/lib/python/debugpy/../debugpy/server/cli.py", line 285, in run_file
    runpy.run_path(target_as_str, run_name=compat.force_str("__main__"))
  File "/opt/conda/lib/python3.8/runpy.py", line 265, in run_path
    return _run_module_code(code, init_globals, run_name,
  File "/opt/conda/lib/python3.8/runpy.py", line 97, in _run_module_code
    _run_code(code, mod_globals, init_globals,
  File "/opt/conda/lib/python3.8/runpy.py", line 87, in _run_code
    exec(code, run_globals)
  File "/opt/ml/code/EfficientNet_cross_level_1/main.py", line 17, in <module>
    train_image_dataset(K, 2)
  File "/opt/ml/code/EfficientNet_cross_level_1/train.py", line 214, in train_image_dataset
    _ = train(model, criterion, optimizer, scheduler, dataloaders, num_epochs=set_epoch)
  File "/opt/ml/code/EfficientNet_cross_level_1/train.py", line 33, in train
    for inputs, labels in tqdm(dataloader[phase]):
  File "/opt/conda/lib/python3.8/site-packages/tqdm/std.py", line 1171, in __iter__
    for obj in iterable:
  File "/opt/conda/lib/python3.8/site-packages/torch/utils/data/dataloader.py", line 435, in __next__
    data = self._next_data()
  File "/opt/conda/lib/python3.8/site-packages/torch/utils/data/dataloader.py", line 1085, in _next_data
    return self._process_data(data)
  File "/opt/conda/lib/python3.8/site-packages/torch/utils/data/dataloader.py", line 1111, in _process_data
    data.reraise()
  File "/opt/conda/lib/python3.8/site-packages/torch/_utils.py", line 428, in reraise
    raise self.exc_type(msg)
KeyError: Caught KeyError in DataLoader worker process 0.
Original Traceback (most recent call last):
  File "/opt/conda/lib/python3.8/site-packages/pandas/core/indexes/base.py", line 2898, in get_loc
    return self._engine.get_loc(casted_key)
  File "pandas/_libs/index.pyx", line 70, in pandas._libs.index.IndexEngine.get_loc
  File "pandas/_libs/index.pyx", line 101, in pandas._libs.index.IndexEngine.get_loc
  File "pandas/_libs/hashtable_class_helper.pxi", line 1032, in pandas._libs.hashtable.Int64HashTable.get_item
  File "pandas/_libs/hashtable_class_helper.pxi", line 1039, in pandas._libs.hashtable.Int64HashTable.get_item
KeyError: 1512
The above exception was the direct cause of the following exception:
Traceback (most recent call last):
  File "/opt/conda/lib/python3.8/site-packages/torch/utils/data/_utils/worker.py", line 198, in _worker_loop
    data = fetcher.fetch(index)
  File "/opt/conda/lib/python3.8/site-packages/torch/utils/data/_utils/fetch.py", line 44, in fetch
    data = [self.dataset[idx] for idx in possibly_batched_index]
  File "/opt/conda/lib/python3.8/site-packages/torch/utils/data/_utils/fetch.py", line 44, in <listcomp>
    data = [self.dataset[idx] for idx in possibly_batched_index]
  File "/opt/ml/code/EfficientNet_cross_level_1/dataset.py", line 111, in __getitem__
    image_path = '/'.join([train_image, self.df['path'][idx], self.df['file'][idx]])
  File "/opt/conda/lib/python3.8/site-packages/pandas/core/series.py", line 882, in __getitem__
    return self._get_value(key)
  File "/opt/conda/lib/python3.8/site-packages/pandas/core/series.py", line 990, in _get_value
    loc = self.index.get_loc(label)
  File "/opt/conda/lib/python3.8/site-packages/pandas/core/indexes/base.py", line 2900, in get_loc
    raise KeyError(key) from err
KeyError: 1512